Workbook

Sheet 여행 일정
A1: 도쿄 가족여행 | 맛집과 정원 카페 4박 5일
A2: 2026.10.01(목)~10.05(월) · 성인 3명 기준 · 확인일 2026.09.27 · 10/1 수정 · 시부야 스카이 제외
A3: 10/1 수정안: 시각은 목표입니다. 확정 예약은 우나후지 10/3(토) 17:00 한 곳. 기본은 10/2 가마쿠라이며, 날씨에 따라 2·3일의 낮 일정만 교체하고 저녁(10/2 신발·이른 저녁, 10/3 우나후지)은 날짜 그대로 둡니다.
A4: 원본 299곳을 후보로 읽고 동선·메뉴·영업 조건으로 선별했습니다. 미확인 목록 73건은 일정에 넣지 않았으며, 299곳 전체의 최신 리뷰를 검증한 것은 아닙니다.
A5: 하루 주 카페 1곳. 서부 일정일은 카나데 14:00~15:30, 네즈·사샤는 교체 후보입니다. 하마리큐 다실·사후는 10/4가 요코하마 저녁으로 바뀌어 이번에는 넣지 않았습니다.
A6: 01 날짜별 동선 | 낮에는 관광, 저녁은 예약 가능한 식사 중심
A7: 날짜 | B7: 동선·오전 | C7: 점심 | D7: 저녁 | E7: 간식·휴식 | F7: 바꿀 때의 기준
A8: 46296 | B8: 목요일 · 도착 나리타 → 신주쿠 → 숙소 기존 가이드 도착 16:30 기준 | C8: 기내 또는 출발 전 도쿄 점심 예약 없음 | D8: 20:15 이후 목표 고기 저녁(신주쿠산초메) ① 야키니쿠 우시고로 (L.O. 22:30, 03-3358-4129) ② 에이징 비프 (L.O. 22:00, 03-6273-2985) | E8: 이날은 관광·술자리 추가 없음 숙소 복귀와 수면 우선 | F8: 3명 예산 10~15만 원(약 11,400~17,400엔) 코스는 상한을 넘으니 단품 위주 늦거나 피곤하면 하야시다 라멘
A9: 46297 | B9: 금요일 · 가마쿠라 (아침 일찍) 07:30 신주쿠 출발(쇼난신주쿠라인 즈시행) 08:40 대불 또는 하세데라 → 09:50 고마치도리·하치만구 12:30 가마쿠라 출발 → 13:45 숙소에서 쉬기 15:40 숙소 출발 | C9: 11:10 가마쿠라 아키모토 시라스·현지 채소 | D9: 16:00 오다큐 백화점 신주쿠점 2F 엄마 신발: MARGARET HOWELL idea 플랫슈즈 132505 LBG(라이트 베이지) 17:00 츠나하치 총본점 이른 저녁 17:40 개인 약속으로 따로 이동, 부모님은 택시로 숙소 | E9: 대불 또는 하세데라 중 1곳(다리가 괜찮으면 둘 다) 하치만구 본궁 계단(약 60단)이 힘들면 아래에서 참배 13:45~15:30 숙소 휴식 | F9: 10/2 오전 비가 많으면 10/3과 낮 일정 교체 생시라스 미입고 → 익힌 시라스 신발 재고는 미리 전화(03-5325-0722) 없으면 도부 이케부쿠로 2F(03-5951-6599) 저녁 일정은 날짜 고정
A10: 46298 | B10: 토요일 · 서부 도쿄 09:00 메이지신궁 짧게 오모테산도 → 메구로(카나데) → 하쓰다이 16:00 하쓰다이로 이동 | C10: 10:45 도착 / 11:00 목표 마이센 아오야마 본점 돈가스 정식 | D10: 17:00 우나후지 오페라시티 53F 예약 완료 · 상 히츠마부시 18:45 오모이데 요코초 산책(선택) 이후 택시로 숙소 | E10: 14:00~15:30 카나데 라운지 네즈·사샤는 카나데 대체 후보 기본안에 두 카페를 더하지 않음 | F10: 비·피로 시 메이지신궁 생략 가마쿠라 10/3 선택 시 낮 일정만 10/2로 우나후지 17:00은 10/3 그대로 카나데 예약은 변경 가능 여부 확인
A11: 46299 | B11: 일요일 · 아사쿠사 → 요코하마의 밤 09:30 아사쿠사 → 12:30 아키하바라 가이요도 하비로비 13:30 숙소에서 쉬기 → 15:45 요코하마로 16:45 에어 캐빈(해 지는 시각 17:23) | C11: 11:00 나미키 야부소바 소바·튀김 저녁 노게를 위해 가볍게 | D11: 18:00 요코하마 노게 저녁 노게노 다이도코로 파오시티(97석, 일 12~23시) 핫페퍼 예약 권장 · 안 되면 피오시티 지하 2층 19:45 출발, 21:00경 숙소 | E11: 13:30~15:30 숙소 휴식 에어 캐빈 왕복 1,800엔(성인) 운하파크에서 미나토미라이 야경 | F11: 아키하바라 가게는 실내라 비가 와도 그대로 강풍으로 에어 캐빈이 멈추면 역 앞에서 야경만 피곤하면 요코하마를 빼고 숙소 근처에서 저녁 폰가·에비스·긴자는 이번 일정에서 제외
A12: 46300 | B12: 월요일 · 귀국 09:30 짐 정리·체크아웃 준비 10:20 숙소 출발(택시) → 신주쿠역 11:08 N'EX 21호 → 공항제2빌딩 12:27 | C12: 역 도시락·가벼운 포장 유명 식당 줄서기 없음 | D12: 귀국 후 식사 도쿄 식사 예산에 제외 | E12: 음료·간식은 공항에서 여유 있게 출국 전 쇼핑을 위해 늦게 출발하는 계획은 피함 | F12: N'EX 21호(신주쿠 11:08 → 공항제2빌딩 12:27, 평일 시각) 대안: 11:38 발 23호(12:54) · 10:38 발 19호(11:53) 제3터미널은 역에서 걸어서 약 15분, 12:45경 도착 ZE610 16:20 · 10/5는 한국 대체공휴일이라 붐빔
A14: 2일↔3일 교체: 가마쿠라와 서부 도쿄(메이지신궁·마이센·카나데)의 낮 일정만 서로 바꿉니다. 저녁은 날짜 고정: 10/2 엄마 신발(오다큐)·츠나하치·개인 약속, 10/3 우나후지 17:00 예약. 요코하마는 10/4 저녁.
A16: 02 식비와 카페 입장료 | 계획 예산, 단위 JPY
A17: 성인 인원 | B17: 3 | C17: 아침 1회 예산 | D17: 1000 | E17: 아침 횟수 | F17: 4
A18: 구분 | B18: 항목 | C18: 1인 하한 | D18: 1인 상한 | E18: 가족 하한 | F18: 가족 상한
A19: 10/1 저녁 | B19: 고기 저녁 (우시고로 또는 에이징 비프, 3명 10~15만 원) | C19: 3800 | D19: 5800 | E19: =C19*$B$17 -> 11400 | F19: =D19*$B$17 -> 17400
A20: 10/2 점심 | B20: 가마쿠라 아키모토 | C20: ='맛집 상세'!E8 -> 2500 | D20: ='맛집 상세'!F8 -> 3500 | E20: =C20*$B$17 -> 7500 | F20: =D20*$B$17 -> 10500
A21: 10/2 저녁 | B21: 츠나하치 총본점 (10/2 이른 저녁) | C21: ='맛집 상세'!E9 -> 2500 | D21: ='맛집 상세'!F9 -> 4500 | E21: =C21*$B$17 -> 7500 | F21: =D21*$B$17 -> 13500
A22: 10/3 점심 | B22: 마이센 아오야마 본점 | C22: ='맛집 상세'!E10 -> 2500 | D22: ='맛집 상세'!F10 -> 3500 | E22: =C22*$B$17 -> 7500 | F22: =D22*$B$17 -> 10500
A23: 10/3 저녁 | B23: 우나후지 도쿄 오페라시티점 (예약 완료) | C23: ='맛집 상세'!E13 -> 6500 | D23: ='맛집 상세'!F13 -> 8500 | E23: =C23*$B$17 -> 19500 | F23: =D23*$B$17 -> 25500
A24: 10/4 점심 | B24: 나미키 야부소바 | C24: ='맛집 상세'!E12 -> 1500 | D24: ='맛집 상세'!F12 -> 2500 | E24: =C24*$B$17 -> 4500 | F24: =D24*$B$17 -> 7500
A25: 10/4 저녁 | B25: 요코하마 노게 저녁 (파오시티 등, 예약 권장) | C25: 3000 | D25: 5000 | E25: =C25*$B$17 -> 9000 | F25: =D25*$B$17 -> 15000
A26: 10/5 점심 | B26: 역 도시락·포장 | C26: 1500 | D26: 2000 | E26: =C26*$B$17 -> 4500 | F26: =D26*$B$17 -> 6000
A27: 아침 | B27: 1회 예산 × 횟수 | C27: =$D$17*$F$17 -> 4000 | D27: =$D$17*$F$17 -> 4000 | E27: =C27*$B$17 -> 12000 | F27: =D27*$B$17 -> 12000
A28: 카페 | B28: 카나데 라운지 | C28: ='맛집 상세'!E23 -> 1600 | D28: ='맛집 상세'!F23 -> 4200 | E28: =C28*$B$17 -> 4800 | F28: =D28*$B$17 -> 12600
A29: 교체 후보 | B29: 네즈: 기본 합계 제외 | C29: 0 | D29: 0 | E29: 0 | F29: 0
A30: 카페 | B30: 나카지마노 오차야 (이번 일정 제외) | C30: 0 | D30: 0 | E30: =C30*$B$17 -> 0 | F30: =D30*$B$17 -> 0
A31: 추가 간식 | B31: 위 카페 외 여행 전체 여유액 | C31: 1000 | D31: 2000 | E31: =C31*$B$17 -> 3000 | F31: =D31*$B$17 -> 6000
A32: 식비 소계 | B32: 주요 식사 + 카페 2곳 포함 | C32: =SUM(C19:C31) -> 30400 | D32: =SUM(D19:D31) -> 45500 | E32: =SUM(E19:E31) -> 91200 | F32: =SUM(F19:F31) -> 136500
A34: 교체 후보 | B34: 네즈 입장료: 기본 합계 제외 | C34: 0 | D34: 0 | E34: 0 | F34: 0
A35: 입장료 | B35: 요코하마 에어 캐빈 왕복 / 성인 | C35: 1800 | D35: 1800 | E35: =C35*$B$17 -> 5400 | F35: =D35*$B$17 -> 5400
A36: 입장 소계 | B36: 에어 캐빈 왕복만(대불·하세데라 입장료 별도) | C36: =SUM(C34:C35) -> 1800 | D36: =SUM(D34:D35) -> 1800 | E36: =SUM(E34:E35) -> 5400 | F36: =SUM(F34:F35) -> 5400
A37: 총계 | B37: 식비 + 위 입장료 | C37: =C32+C36 -> 32200 | D37: =D32+D36 -> 47300 | E37: =E32+E36 -> 96600 | F37: =F32+F36 -> 141900
A38: 카나데는 세금·서비스 15% 포함. 네즈 선택 시 카나데를 빼고 네즈 음료 800~1,700엔+입장 1,400엔/인을 더합니다. 총계는 항공·숙박·교통·쇼핑·기타 관광 입장료(대불 300엔·하세데라 400엔 등) 제외.
A40: 03 출발 전 먼저 처리할 것 | 예약·티켓 결제는 아직 하지 않음
A41: 우선순위 | B41: 대상 | C41: 희망 시각 | D41: 확인할 것 | E41: 현재 상태 | F41: 주의
A42: 1 | B42: 우나후지 오페라시티 | C42: 10/3(토) 17:00 | D42: 예약 확인 메일·문자를 가족과 공유 | E42: 예약 완료 | F42: 10/4에서 10/3으로 변경. 창가·좌석은 예약 내역 기준. 하쓰다이역 53F 전용 승강기.
A43: 2 | B43: 노게노 다이도코로 파오시티 | C43: 10/4(일) 18:00 | D43: 성인 3명 테이블 · 핫페퍼 온라인 예약 | E43: 미예약 · 예약 권장 | F43: 일요일 저녁이라 붐빌 수 있음. 안 되면 사쿠라기초역과 바로 이어진 피오시티 지하 2층 선술집 거리에서 빈자리.
A44: 3 | B44: 엄마 신발 · 오다큐 신주쿠 2F | C44: 10/2(금) 16:00 | D44: MARGARET HOWELL idea 플랫슈즈 132505 LBG · 엄마 사이즈 재고 | E44: 전화 확인 전 | F44: 오다큐 03-5325-0722. 없으면 도부 이케부쿠로 2F 같은 브랜드(03-5951-6599)에 재고 확인. 점원에게 보여줄 일본어 카드는 웹 가이드에 있음.
...

Sheet 맛집 상세
A1: 맛집 상세 | 기존 식당·간식 15곳 + 분위기 카페 6곳
A2: 기준일 2026.09.27 · 10/1 수정. E·F열은 1인 1회 계획 예산입니다. 고정 메뉴값이 확인된 경우 D·H·I열에 별도로 적었습니다. 대안 식당은 기본 식비 합계에 중복 반영하지 않았습니다.
A3: 지도: 기존 목록과 동일한 지점은 원본 링크를 유지했습니다. 신규 후보와 시세이도 3F 카페는 상호·주소 검색 링크로, 특정 장소 ID가 검증된 링크와 구분됩니다.
A4: 공식 안내도 임시휴무·재고·만석을 보장하지 않습니다. I열은 확인 근거, K열은 대표 출처, L열은 추가 대조 출처입니다. 빈 L열은 추가 링크 없음입니다.
A6: 번호 | B6: 사용 구분 | C6: 상호·지점 / 주소 | D6: 대표 메뉴 · 고른 이유 | E6: 하한 JPY | F6: 상한 JPY | G6: 영업 · 예약 조건 | H6: 가족 방문 · 주의사항 | I6: 확인 근거 · 원본 | J6: 지도 | K6: 대표 출처 | L6: 보조 출처
A7: 1 | B7: 일정 10/1 저녁 | C7: 라멘 하야시다 신주쿠 본점 らぁ麺 はやし田 新宿本店 新宿3-31-5 ペガサス館102 TEL 03-6380-0047 | D7: 간장 라멘 오리와 닭을 쓰는 육수가 특징. 도착일에 무거운 코스 대신 한 그릇으로 마무리. | E7: 1500 | F7: 2000 | G7: 매일 11:00~23:00 20:15 이후 도착 상황에 맞춰 방문. 예약 식사로 묶지 않음. | H7: 예상 대기가 20분을 넘으면 교자노 후쿠호로 전환. 입국·수하물 지연 시 맛집보다 체크인과 휴식 우선. | I7: 원본 #136 / 143행 영업시간·육수: 운영사 공식 | J7: 원본 지도 | K7: 출처 보기
A8: 2 | B8: 일정 10/2 점심 | C8: 가마쿠라 아키모토 鎌倉 秋本 鎌倉市小町1-6-15 i-ZA鎌倉3F TEL 0467-25-3705 | D8: 시라스 덮밥·가마쿠라 채소 가마쿠라에 간 날 현지 식재료를 먹는 선택. 생시라스가 없으면 가마아게(삶은 시라스)로. | E8: 2500 | F8: 3500 | G8: 점심 11:00~15:30 / 목요일 휴무 예약 불가. 금요일 10:45 도착 목표. | H8: 생시라스는 당일 수급에 따라 다름. 대기 30분을 넘으면 근처에서 익힌 시라스 메뉴로 변경. 3F 승강기 여부 미확인. | I8: 기존 가이드 유지 영업: 가마쿠라 관광협회 예약: 타베로그 | J8: 지도 검색 | K8: 출처 보기 | L8: 대조 보기
A9: 3 | B9: 일정 10/2 이른 저녁 | C9: 츠나하치 총본점 新宿つな八 総本店 新宿3-31-8 | D9: 덴푸라 정식 1924년 창업. 오다큐 신발 쇼핑 뒤 17:00에 이른 저녁. 개인 약속이 있는 날이라 짧고 편한 식사로 선택. | E9: 2500 | F9: 4500 | G9: 매일 11:00~22:00 / 주문마감 21:00 연중무휴(12/31·1/1 제외) 예약 없이 17:00 방문 목표. | H9: 대기 20분을 넘으면 근처 다른 식당으로. 식사 후 부모님은 택시로 숙소(약 5~10분). | I9: 10/1 추가 영업: 핫페퍼·타베로그 교차확인 예산은 계획용 추정 | J9: 지도 검색 | K9: 출처 보기 | L9: 대조 보기
A10: 4 | B10: 일정 10/3 점심 | C10: 마이센 아오야마 본점 とんかつ まい泉 青山本店 神宮前4-8-5 TEL 050-3188-5802 | D10: 히레카츠 또는 로스카츠 정식 메이지신궁 다음 오모테산도 방향에 있어 음식 때문에 멀리 돌아가지 않아도 됨. | E10: 2500 | F10: 3500 | G10: 11:00~22:00 / 주문마감 21:00 토·일 일반 식사 예약 불가(연회 코스 제외). 10:45 도착, 11:00 식사 목표. | H10: 기름진 음식 부담이 있으면 작은 정식으로. 점심 대기 30분 이상이면 주변 식사로 바꾸고 오후 일정을 지킴. | I10: 기존 가이드 유지 영업·주말 예약 규정: 공식 | J10: 지도 검색 | K10: 출처 보기
A11: 5 | B11: 보류 이번 일정 제외 | C11: 야키니쿠 폰가 에비스 焼肉ぽんが 恵比寿店 恵比寿西1-21-5 Sreed EBISU+t 2F TEL 050-5447-8698 | D11: 네기탄·와규 구이 고기 좋아하는 가족의 마지막 밤 저녁. 1만 엔 코스 선택 시 서비스료를 별도로 계산. | E11: 12000 | F11: 14000 | G11: 17:00~익일 03:00 10/4(일) 18:00 3명 예약 필요 / 미예약 예약 15분 지각 시 자동 취소 안내. | H11: 공식 코스 10,000엔(세금 포함)+서비스 10%=11,000엔, 음료 별도. 생·덜 익힌 소고기/내장 메뉴 교체 가능 여부와 2F 엘리베이터를 예약 전 확인. | I11: 원본 #243 / 250행 코스·서비스료: 공식 예산에는 소량 음료 여유 포함 | J11: 원본 지도 | K11: 출처 보기 | L11: 대조 보기
A12: 6 | B12: 일정 10/4 점심 | C12: 나미키 야부소바 並木藪蕎麦 雷門2-11-9 TEL 03-3841-1340 | D12: 자루소바 또는 덴푸라 소바 저녁 노게를 고려해 가벼운 점심으로 선택. 타베로그 소바 EAST 백명점 2025 선정 확인. | E12: 1500 | F12: 2500 | G12: 11:00~19:30 / 주문마감 19:00 수·목 휴무 / 예약 불가 일요일 11:00 개점 방문 목표. | H12: 메밀 알레르기가 있으면 제외. 소바만으로 부족하면 튀김을 곁들이되 점심을 과하게 늘리지 않음. | I12: 원본 #168 / 175행 영업·선정 이력: 타베로그 공식 웹사이트 미확인 | J12: 원본 지도 | K12: 출처 보기
A13: 7 | B13: 일정 10/3 저녁 · 예약 완료 | C13: 우나후지 도쿄 오페라시티점 炭焼 うな富士 東京オペラシティ店 西新宿3-20-2 東京オペラシティ53F TEL 03-6457-5266 | D13: 상 히츠마부시 장어구이를 그대로, 약미와 함께, 육수에 말아 먹는 메뉴. 기존 희망 장소를 유지. | E13: 6500 | F13: 8500 | G13: 저녁 17:00~22:00 / 주문마감 21:00 10/3(토) 17:00 예약 완료 부정기 휴무. | H13: 개인실은 저녁 별도 3,000엔/120분 안내. 기본 예산은 일반석 기준. 창가·야경·좌석을 보장하지 않음. 하쓰다이역에서 53F 전용 승강기 이용. | I13: 기존 가이드 유지 운영·개인실: 공식 상 히츠마부시 5,950엔: EAT도쿄 | J13: 지도 검색 | K13: 출처 보기 | L13: 대조 보기
A14: 8 | B14: 예비 간식 10/3 생략 가능 | C14: 나나야 아오야마 ななや 青山店 渋谷2-7-12 | D14: 말차 젤라토 중간 농도와 진한 농도를 비교. 가장 진한 맛이 반드시 모두에게 맞는 것은 아님. | E14: 600 | F14: 1000 | G14: 11:00~19:00 / 화요일 휴무 정원 카페를 택한 기본안에는 넣지 않음. 네즈 방문을 빼는 경우에만 점심 뒤 선택. | H14: 우유 성분·알레르기 확인. 카페 휴식 대신으로 계산하지 않음. 배가 부르면 생략. | I14: 원본 #94 / 101행 운영: 공식 계정·시즈오카현 자료 | J14: 원본 지도 | K14: 출처 보기 | L14: 대조 보기
A15: 9 | B15: 선택 간식 10/4 | C15: 가메주 亀十 雷門2-18-11 TEL 03-3841-2210 | D15: 도라야키 포장 아사쿠사 점심 뒤 가족끼리 나눠 먹거나 숙소 간식으로. | E15: 500 | F15: 1000 | G15: 10:00 개점 안내 점심 전후에만 방문 제안. 폐점·임시휴무는 당일 재확인. | H15: 대기 15~20분이 넘으면 건너뜀. 포장 간식이며 앉아서 쉬는 장소로 배치하지 않음. | I15: 원본 #179 / 186행 개점·상품: 아사쿠사 상점가 가격은 계획용 추정 | J15: 원본 지도 | K15: 출처 보기
A16: 10 | B16: 보류 이번 일정 제외 | C16: 시세이도 팔러 긴자 살롱 드 카페 資生堂パーラー 銀座本店サロン・ド・カフェ 3F 銀座8-8-3 東京銀座資生堂ビル3F | D16: 정규 딸기/초콜릿 파르페 또는 커피 정규 파르페 2,400엔, 커피 1,300엔 안내. 10월 한정 메뉴는 미확인. | E16: 1300 | F16: 3700 | G16: 일요일 11:00~20:00 / 주문마감 19:30 예약 불가. 하마리큐를 생략하거나 우천일 때 14시 전후 대안. | H16: 원본 #22의 4·5F 레스토랑과 다른 3F 카페. 대기가 20분을 넘으면 근처 빈자리 있는 카페로. 9월 포도 파르페를 10월 확정 메뉴로 넣지 않음. | I16: 원본 #22 / 29행에서 파생 다른 층 매장 별도 확인 가격·예약: 공식 | J16: 지도 검색 | K16: 출처 보기
A17: 11 | B17: 대안 10/1 저녁 | C17: 교자노 후쿠호 신주쿠점 餃子の福包 新宿店 新宿2-8-6 KDX新宿286ビル1F TEL 03-5367-1582 | D17: 군만두·물만두·밥 라멘 대기가 길거나 부모님이 만두를 선호할 때. 마늘 없는 교자 선택 가능. | E17: 1500 | F17: 2500 | G17: 평일 11:30~15:30 / 17:00~23:00 예약 불가. 저녁 주문마감 22:20 안내. | H17: 같은 신주쿠의 GYO PAO(餃包)와 다른 가게. 관광 사이트 일부에 심야 영업 옛 정보가 있어 늦은 밤에는 전화 확인. | I17: 원본 #157 / 164행 메뉴: 공식 영업: 타베로그·산토리 교차확인 | J17: 원본 지도 | K17: 출처 보기 | L17: 대조 보기
A18: 12 | B18: 보류 이번 일정 제외 | C18: 스시노 미도리 시부야점 梅丘寿司の美登利 渋谷店 道玄坂1-12-3 マークシティイースト4F TEL 03-5458-0002 | D18: 니기리 모둠·계절 스시 폰가 예약이 안 되거나 고기보다 스시를 원할 때 10/4 저녁 대체. | E18: 3000 | F18: 5000 | G18: 토·일 11:00~21:00 / 주문마감 20:30 공식 페이지 예약·대기 안내 확인 후 선택. 빈자리 미확인. | H18: 폰가 예약이 안 될 때 에비스 그릇 가게 뒤 JR로 시부야까지 1정거장. 긴자 라이온과 둘 중 하나만 고르고 두 곳을 함께 예약하지 않음. | I18: 기존 후보 유지 지점·영업·대기 방식: 공식 예산은 추정 | J18: 지도 검색 | K18: 출처 보기
A19: 13 | B19: 대안 10/4 점심 교체 | C19: 이마한 별관 今半別館 浅草2-2-5 TEL 03-3841-2690 | D19: 스키야키 가벼운 소바보다 스키야키가 더 중요한 경우에만 선택. 같은 날 저녁 장어와 양·비용을 함께 조정. | E19: 12100 | F19: 15000 | G19: 좌석 홀은 예약 불가. 방 예약은 지정 코스 조건. 임박 예약은 전화 문의. 영업시간·가용 좌석 재확인. | H19: 원래 가이드의 浅草今半 国際通り本店과 다른 매장. 12,100엔은 별관 코토토이 코스 세금·서비스 포함 가격이며 최저 단품 가격이 아님. | I19: 원본 #170 / 177행 별관 공식 요금·예약 규정 동명 다른 업체와 구분 | J19: 원본 지도 | K19: 출처 보기 | L19: 대조 보기
A20: 14 | B20: 보류 이번 일정 제외 | C20: 프레데릭 카셀 긴자 미쓰코시 フレデリック・カッセル 銀座三越店 銀座4-6-16 銀座三越B2F | D20: 밀푀유 포장 시세이도 파르페 대신 제과류를 원할 때 선택. 디저트 두 곳을 필수로 채우지 않음. | E20: 1000 | F20: 1800 | G20: 백화점 당일 영업·상품 재고 확인 오후 방문 후보, 특정 판매 시각 확정하지 않음. | H20: 포장 매장. 휴식용 카페가 아님. 생과자 보관·운반 조건을 확인하고 바로 먹거나 숙소 복귀 전에 구입. | I20: 원본 #32 / 39행 공식 브랜드·미쓰코시 보조 링크는 2024년 공지: 재고/판매시각 근거로 사용하지 않음 | J20: 원본 지도 | K20: 출처 보기 | L20: 대조 보기
A21: 15 | B21: 보류 영업 확인 후 | C21: 키리무기야 진로쿠 신주쿠교엔점 切麦や 甚六 新宿御苑店 新宿1-17-1 LAND・DENビル TEL 03-6273-2646 | D21: 우동·덴푸라 숙소 인근 후보지만 목요일 저녁 운영정보가 상충해 도착일 일정에는 넣지 않음. | E21: 1500 | F21: 2500 | G21: 공식 매장 페이지: 저녁 17:30~23:30 타베로그: 화·목·금 저녁 미운영 전화 확인 전 어느 쪽도 확정하지 않음. | H21: 이름이 같은 다른 지점으로 바꾸지 않음. 10/1 저녁 이용 가능 여부를 확인한 경우에만 하야시다와 교체. | I21: 원본 #153 / 160행 공식·타베로그 불일치 발견 당일 영업 미확인 | J21: 원본 지도 | K21: 출처 보기 | L21: 대조 보기
A22: 16 | B22: 교체 카페 카나데 대신 | C22: 네즈카페 NEZUCAFÉ / ネヅカフェ 港区南青山6-5-1 根津美術館内 TEL 03-3400-2536 | D22: 정원을 둘러싼 유리창과 녹음 미술관·정원과 함께 머물 때 추천. 커피 800엔, 케이크 800엔. 오후 카나데를 생각해 여기서는 음료만 마셔도 좋음. | E22: 800 | F22: 1700 | G22: 10:00~16:30 / 음식 주문 15:00, 음료 16:00 마감 카페 예약 불가. 미술관 입장객만 이용. 10/5(월) 휴관. | H22: 카나데 대신 선택. 미술관 성인 온라인 1,400엔 별도, 카페 예약 불가. 기본 합계에서 제외. 10/5 월요일 휴무. 미술관 표는 카페 좌석을 보장하지 않음. | I22: 추가 카페 / 공식 카페·티켓 10/3은 8/15~10/12 전시 기간 E·F는 카페 비용만, 입장료 별도 | J22: 지도 검색 | K22: 출처 보기 | L22: 대조 보기
A23: 17 | B23: 주 카페 서부 일정일 | C23: 카나데 라운지 KANADE LOUNGE / カナデ ラウンジ 目黒区下目黒1-8-1 ホテル雅叙園東京1F TEL 03-6417-0101 | D23: 높은 유리 천장·정원·폭포 전망 가족끼리 오래 앉아 쉬는 특별한 공간으로 최우선. 커피 1,600엔, 케이크 2,000엔. 차와 케이크는 약 4,100~4,200엔. | E23: 1600 | F23: 4200 | G23: 10:30~22:30 / 주문마감 21:30 케이크 14:00~17:00 14:00 좌석만 예약 희망 / 빈자리 미확인 | H23: 기본 10/3 14:00~15:30, 가마쿠라를 10/3으로 바꾸면 10/2 방문. 날짜 변경 시 실제 예약도 별도 변경해야 함. 2시간 이용·10분 무연락 지각 시 취소 안내. 금액은 세금·서비스 15% 포함. | I23: 공식 메뉴 PDF·예약 페이지 확인 좌석 가용 여부 미확인 계절 파르페의 10월 판매 미확인 | J23: 지도 검색 | K23: 출처 보기 | L23: 대조 보기
A24: 18 | B24: 보류 이번 일정 제외 | C24: 나카지마노 오차야 中島の御茶屋 / Nakajima-no-Ochaya 中央区浜離宮庭園1-1 浜離宮恩賜庭園内 TEL 03-3541-0200 | D24: 연못 한가운데서 말차·화과자 커피숍보다 일본 정원 다실에 가까움. 하마리큐 산책과 차 한 잔을 한 코스로 묶을 때 추천. | E24: 900 | F24: 1500 | G24: 다실 9:00~16:45 / 주문마감 16:30 정원 9:00~17:00 / 입장마감 16:30 일반 방문 기준. 특정 다회 행사 예약 아님. | H24: 정원 입장료 성인 300엔 별도(65세 이상 150엔, 증빙 필요). E·F는 현재 확정 메뉴값이 아닌 차·과자 예산 추정. 비·보행 부담 시 대체. 좌석 형태·단차는 방문 전 확인. | I24: 추가 카페 / 도쿄도공원협회 공식 차·화과자 최신 가격 미확인 2026 대다회 10/31~11/1: 여행 기간 아님 | J24: 지도 검색 | K24: 출처 보기 | L24: 대조 보기
A25: 19 | B25: 교체 카페 10/3 대안 | C25: 사샤 카네타나카 茶洒 金田中 / Sahsya Kanetanaka 港区北青山3-6-1 オーク表参道2F TEL 03-6450-5116 | D25: 이끼 정원·절제된 건축·일본식 디저트 와라비모치 1,650엔 안내. 차와 함께 2,000~3,500엔 계획. 호텔 라운지보다 미니멀한 공간을 원할 때. | E25: 2000 | F25: 3500 | G25: 11:30~22:00 / 카페 14:00~주문마감 21:00 일반 카페 예약 불가. 예약 가능한 식사 코스와 혼동하지 않음. | H25: 13세 미만 입장 불가 안내. 일반 카페는 예약 불가. 네즈·카나데 대신 14:00 방문 후 하쓰다이(우나후지)로 이동. 세 카페를 모두 넣지 않음. 서비스료 없음. | I25: 추가 카페 / 매장 관리 공식 타베로그·구루나비 카페 EAST 백명점 2025 음료 포함 총액은 예산 추정 | J25: 지도 검색 | K25: 출처 보기 | L25: 대조 보기
A26: 20 | B26: 반일 교체 동선 별도 | C26: 오리엔토 카페 オリエント・カフェ / Orient Café 文京区本駒込2-28-21 東洋文庫内 TEL 03-3942-0400 | D26: 시볼트 정원·목재 테이블·고이와이 디저트 동양문고와 함께 보내는 한적한 반일 코스 후보. 치즈케이크·차 중심으로 계획. | E26: 1500 | F26: 2500 | G26: 디저트 11:30~17:00 화요일·동양문고 휴관일 휴무 예약 페이지 있음. 카페 이용 예약 조건은 별도 문의. | H26: 현재 일정에서 일부러 왕복하기엔 멂. 아사쿠사·하마리큐 반일을 대체하거나 다음 여행 후보. 모리슨 서고는 카페 내부가 아닌 별도 박물관. 카페만 이용 시 입장 조건 확인 필요. | I26: 추가 카페 / 운영사·공식 예약 공식 공지의 10월 대관일은 7·17·18·24일 예산 추정, 당일 임시휴무 재확인 | J26: 지도 검색 | K26: 출처 보기 | L26: 대조 보기
A27: 21 | B27: 보류 이번 일정 제외 | C27: 카페 다이닝 사후 カフェダイニング 茶楓 / SAFU by Onko Chishin 港区虎ノ門4-1-35 菊池寛実記念 智美術館内 TEL 03-6453-0097 | D27: 정원을 바라보는 차분한 다이닝 호지차 시폰·키나코 크림 등 디저트와 차. 하마리큐를 걷기 어려운 비 오는 날 후보. | E27: 2000 | F27: 3500 | G27: 11:00~18:00 / 월요일 휴무 디저트 카페 메뉴는 15:00~18:00(주문마감 17:30) 예약은 런치만, 카페 예약 불가. | H27: 10/5(월)에는 넣지 않음. 일요일 대체안은 긴자 짧게 → 15:00~15:45 사후 → 에비스 저녁. 대기 있으면 가까운 카페로 변경. 단차·카페만 이용 시 입장 조건 확인 필요. | I27: 추가 카페 / 공식 사이트·카페 메뉴 금액은 계획용 추정 11시 개점과 15시 디저트 시작 구분 | J27: 지도 검색 | K27: 출처 보기 | L27: 대조 보기
A29: 추천 우선순위는 별점순이 아닙니다. 로바타의 계단, 폰가의 높은 비용, 카페의 입장권·무예약 조건도 함께 반영했습니다. 같은 이름의 다른 지점·다른 층으로 혼동하지 마세요.
A31: 카나데 금액·서비스료 확인용 공식 메뉴 PDF / 하마리큐 대다회 2026 공식 일정: 이번 여행 기간과 다름 | K31: 메뉴 PDF | L31: 행사 일정
